Workbook

Sheet Summary
A1: (Example Client) — ISO 42001 readiness workbook
A2: (Example Client) · ISO 42001 · generated from the GRC record as of 2026-10-24. Read-only export: change the record through pull requests, not here.
A4: As of | B4: 46319 | C4: The date the record was evaluated; overdue figures count from here.
A5: Applicable requirements | B5: =COUNTIFS('Control matrix'!D:D,"Yes")
A6: Requirements ready | B6: =COUNTIFS('Control matrix'!J:J,"Ready") | C6: Every leg verified on current evidence.
A7: Share ready | B7: =IF(B5=0,0,B6/B5)
A8: Evidence-test legs verified | B8: =COUNTIFS('Control matrix'!F:F,"verified")+COUNTIFS('Control matrix'!G:G,"verified")+COUNTIFS('Control matrix'!H:H,"verified")+COUNTIFS('Control matrix'!I:I,"verified") | C8: Out of 4 per applicable requirement.
A9: Share of legs verified | B9: =IF(B5=0,0,B8/(B5*4))
A10: Open gaps | B10: =COUNTIFS(Gaps!I:I,"open")+COUNTIFS(Gaps!I:I,"in_progress") | C10: Open or in progress.
A11: Overdue gaps | B11: =COUNTIFS(Gaps!J:J,">0") | C11: Open or in progress and past their due date.
A12: Open nonconformities (major) | B12: =COUNTIFS(Findings!B:B,"major",Findings!E:E,"<>closed",Findings!E:E,"<>accepted")
A13: Open nonconformities (minor) | B13: =COUNTIFS(Findings!B:B,"minor",Findings!E:E,"<>closed",Findings!E:E,"<>accepted")
A14: Evidence failing or expired | B14: =COUNTIFS(Evidence!G:G,"FAILING")+COUNTIFS(Evidence!G:G,"EXPIRED")
A15: AI systems with a current, approved impact assessment | B15: =COUNTIFS('Impact assessments'!J:J,"Yes") | C15: Out of 0 AI systems in scope.
A16: Policies and procedures current and approved | B16: =COUNTIFS(Documents!J:J,"Yes") | C16: Out of 17 in the library.
A17: Management review actions open | B17: =COUNTIFS('Review actions'!F:F,"open")

Sheet Control matrix
A1: (Example Client) · ISO 42001 · generated from the GRC record as of 2026-10-24. Read-only export: change the record through pull requests, not here.
A3: ID | B3: Requirement | C3: Type | D3: Applicable | E3: Owner | F3: Documented | G3: Implemented | H3: Evidenced | I3: Tested | J3: State | K3: Gaps | L3: Evidence
A4: 4.1 | B4: Understanding the organization and its context | C4: Clause | D4: Yes | E4: Legal | F4: partial | G4: claimed | H4: not_started | I4: not_started | J4: In progress | K4: GAP-07 | L4: EV-001
A5: 4.2 | B5: Understanding the needs and expectations of interested parties | C5: Clause | D5: Yes | E5: Legal | F5: claimed | G5: not_started | H5: not_started | I5: not_started | J5: Unverified claim | K5: GAP-07
A6: 4.3 | B6: Determining the scope of the AI management system | C6: Clause | D6: Yes | E6: VP Engineering | F6: partial | G6: not_started | H6: not_started | I6: not_started | J6: In progress | K6: GAP-01 | L6: EV-001
A7: 4.4 | B7: AI management system | C7: Clause | D7: Yes | E7: VP Engineering | F7: not_started | G7: not_started | H7: not_started | I7: not_started | J7: Not started
A8: 5.1 | B8: Leadership and commitment | C8: Clause | D8: Yes | E8: VP Engineering | F8: claimed | G8: partial | H8: not_started | I8: not_started | J8: In progress | K8: GAP-09 | L8: EV-016
A9: 5.2 | B9: AI policy | C9: Clause | D9: Yes | E9: VP Engineering | F9: not_started | G9: not_started | H9: not_started | I9: not_started | J9: Not started | K9: GAP-01
A10: 5.3 | B10: Roles, responsibilities and authorities | C10: Clause | D10: Yes | E10: VP Engineering | F10: claimed | G10: not_started | H10: not_started | I10: not_started | J10: Unverified claim | K10: GAP-11
A11: 6.1.1 | B11: Actions to address risks and opportunities - general | C11: Clause | D11: Yes | E11: Security & Compliance | F11: partial | G11: not_started | H11: not_started | I11: not_started | J11: In progress | L11: EV-005
A12: 6.1.2 | B12: AI risk assessment | C12: Clause | D12: Yes | E12: Security & Compliance | F12: partial | G12: verified | H12: verified | I12: not_started | J12: In progress | L12: EV-004, EV-005
A13: 6.1.3 | B13: AI risk treatment | C13: Clause | D13: Yes | E13: Security & Compliance | F13: not_started | G13: partial | H13: not_started | I13: not_started | J13: In progress | K13: GAP-10 | L13: EV-004
A14: 6.1.4 | B14: AI system impact assessment | C14: Clause | D14: Yes | E14: Head of Responsible AI | F14: not_started | G14: not_started | H14: not_started | I14: not_started | J14: Not started | K14: GAP-02
A15: 6.2 | B15: AI objectives and planning to achieve them | C15: Clause | D15: Yes | E15: VP Engineering | F15: not_started | G15: not_started | H15: not_started | I15: not_started | J15: Not started
A16: 6.3 | B16: Planning of changes | C16: Clause | D16: Yes | E16: VP Engineering | F16: not_started | G16: not_started | H16: not_started | I16: not_started | J16: Not started
A17: 7.1 | B17: Resources | C17: Clause | D17: Yes | E17: VP Engineering | F17: claimed | G17: not_started | H17: not_started | I17: not_started | J17: Unverified claim
A18: 7.2 | B18: Competence | C18: Clause | D18: Yes | E18: People Operations | F18: not_started | G18: not_started | H18: not_started | I18: not_started | J18: Not started | K18: GAP-03
A19: 7.3 | B19: Awareness | C19: Clause | D19: Yes | E19: People Operations | F19: not_started | G19: partial | H19: not_started | I19: not_started | J19: In progress | K19: GAP-03 | L19: EV-021
A20: 7.4 | B20: Communication | C20: Clause | D20: Yes | E20: VP Engineering | F20: not_started | G20: not_started | H20: not_started | I20: not_started | J20: Not started
A21: 7.5 | B21: Documented information | C21: Clause | D21: Yes | E21: Security & Compliance | F21: verified | G21: claimed | H21: not_started | I21: not_started | J21: In progress | L21: EV-020
A22: 8.1 | B22: Operational planning and control | C22: Clause | D22: Yes | E22: Head of Platform | F22: partial | G22: partial | H22: not_started | I22: not_started | J22: In progress | K22: GAP-05 | L22: EV-008, EV-009
A23: 8.2 | B23: AI risk assessment (operation) | C23: Clause | D23: Yes | E23: Security & Compliance | F23: partial | G23: verified | H23: verified | I23: not_started | J23: In progress | L23: EV-004, EV-005
A24: 8.3 | B24: AI risk treatment (operation) | C24: Clause | D24: Yes | E24: Security & Compliance | F24: not_started | G24: partial | H24: not_started | I24: not_started | J24: In progress | L24: EV-004
A25: 8.4 | B25: AI system impact assessment (operation) | C25: Clause | D25: Yes | E25: Head of Responsible AI | F25: not_started | G25: not_started | H25: not_started | I25: not_started | J25: Not started | K25: GAP-02
A26: 9.1 | B26: Monitoring, measurement, analysis and evaluation | C26: Clause | D26: Yes | E26: Head of Platform | F26: not_started | G26: partial | H26: not_started | I26: not_started | J26: In progress | L26: EV-012
A27: 9.2 | B27: Internal audit | C27: Clause | D27: Yes | E27: Security & Compliance | F27: not_started | G27: not_started | H27: not_started | I27: not_started | J27: Not started | K27: GAP-08
A28: 9.3 | B28: Management review | C28: Clause | D28: Yes | E28: VP Engineering | F28: not_started | G28: partial | H28: not_started | I28: not_started | J28: In progress | K28: GAP-09 | L28: EV-016
A29: 10.1 | B29: Continual improvement | C29: Clause | D29: Yes | E29: VP Engineering | F29: not_started | G29: not_started | H29: not_started | I29: not_started | J29: Not started
A30: 10.2 | B30: Nonconformity and corrective action | C30: Clause | D30: Yes | E30: Security & Compliance | F30: verified | G30: partial | H30: not_started | I30: not_started | J30: In progress | L30: EV-013, EV-014
A31: A.2.2 | B31: AI policy | C31: Annex A | D31: Yes | E31: VP Engineering | F31: not_started | G31: not_started | H31: not_started | I31: not_started | J31: Not started | K31: GAP-01
A32: A.2.3 | B32: Alignment with other organizational policies | C32: Annex A | D32: Yes | E32: Security & Compliance | F32: not_started | G32: not_started | H32: not_started | I32: not_started | J32: Not started
A33: A.2.4 | B33: Review of the AI policy | C33: Annex A | D33: Yes | E33: Security & Compliance | F33: not_started | G33: not_started | H33: not_started | I33: not_started | J33: Not started
A34: A.3.2 | B34: AI roles and responsibilities | C34: Annex A | D34: Yes | E34: VP Engineering | F34: claimed | G34: not_started | H34: not_started | I34: not_started | J34: Unverified claim | K34: GAP-11
A35: A.3.3 | B35: Reporting of concerns | C35: Annex A | D35: Yes | E35: Legal | F35: not_started | G35: not_started | H35: not_started | I35: not_started | J35: Not started | K35: GAP-12
A36: A.4.2 | B36: Resource documentation | C36: Annex A | D36: Yes | E36: Head of Platform | F36: partial | G36: verified | H36: partial | I36: not_started | J36: In progress | L36: EV-001, EV-002, EV-003
A37: A.4.3 | B37: Data resources | C37: Annex A | D37: Yes | E37: Head of Platform | F37: claimed | G37: not_started | H37: not_started | I37: not_started | J37: Unverified claim | K37: GAP-04
A38: A.4.4 | B38: Tooling resources | C38: Annex A | D38: Yes | E38: Head of Platform | F38: not_started | G38: claimed | H38: not_started | I38: not_started | J38: Unverified claim
A39: A.4.5 | B39: System and computing resources | C39: Annex A | D39: Yes | E39: Head of Platform | F39: not_started | G39: claimed | H39: not_started | I39: not_started | J39: Unverified claim
A40: A.4.6 | B40: Human resources | C40: Annex A | D40: Yes | E40: People Operations | F40: not_started | G40: not_started | H40: not_started | I40: not_started | J40: Not started | K40: GAP-03
A41: A.5.2 | B41: AI system impact assessment process | C41: Annex A | D41: Yes | E41: Head of Responsible AI | F41: not_started | G41: not_started | H41: not_started | I41: not_started | J41: Not started | K41: GAP-02
...

Sheet SoA
A1: (Example Client) · ISO 42001 · generated from the GRC record as of 2026-10-24. Read-only export: change the record through pull requests, not here.
A3: Control | B3: Title | C3: Applicable | D3: Justification | E3: Implementation | F3: State | G3: Owner
A4: A.2.2 | B4: AI policy | C4: Yes | D4: Included: in scope for AI products built and provided by the Innovation and Platform teams. | F4: Not started | G4: VP Engineering
A5: A.2.3 | B5: Alignment with other organizational policies | C5: Yes | D5: Included: in scope for AI products built and provided by the Innovation and Platform teams. | F5: Not started | G5: Security & Compliance
A6: A.2.4 | B6: Review of the AI policy | C6: Yes | D6: Included: in scope for AI products built and provided by the Innovation and Platform teams. | F6: Not started | G6: Security & Compliance
A7: A.3.2 | B7: AI roles and responsibilities | C7: Yes | D7: Included: in scope for AI products built and provided by the Innovation and Platform teams. | F7: Unverified claim | G7: VP Engineering
A8: A.3.3 | B8: Reporting of concerns | C8: Yes | D8: Included: in scope for AI products built and provided by the Innovation and Platform teams. | F8: Not started | G8: Legal
A9: A.4.2 | B9: Resource documentation | C9: Yes | D9: Included: in scope for AI products built and provided by the Innovation and Platform teams. | E9: AI systems inventory and model registry. | F9: In progress | G9: Head of Platform
A10: A.4.3 | B10: Data resources | C10: Yes | D10: Included: in scope for AI products built and provided by the Innovation and Platform teams. | F10: Unverified claim | G10: Head of Platform
A11: A.4.4 | B11: Tooling resources | C11: Yes | D11: Included: in scope for AI products built and provided by the Innovation and Platform teams. | E11: 9 SDLC AI tools listed in the inventory workbook. | F11: Unverified claim | G11: Head of Platform
A12: A.4.5 | B12: System and computing resources | C12: Yes | D12: Included: in scope for AI products built and provided by the Innovation and Platform teams. | E12: 10 infrastructure services listed in the inventory workbook. | F12: Unverified claim | G12: Head of Platform
A13: A.4.6 | B13: Human resources | C13: Yes | D13: Included: in scope for AI products built and provided by the Innovation and Platform teams. | F13: Not started | G13: People Operations
A14: A.5.2 | B14: AI system impact assessment process | C14: Yes | D14: Included: in scope for AI products built and provided by the Innovation and Platform teams. | F14: Not started | G14: Head of Responsible AI
A15: A.5.3 | B15: Documentation of AI system impact assessments | C15: Yes | D15: Included: in scope for AI products built and provided by the Innovation and Platform teams. | F15: Not started | G15: Head of Responsible AI
A16: A.5.4 | B16: Assessing AI system impact on individuals or groups of individuals | C16: Yes | D16: Included: in scope for AI products built and provided by the Innovation and Platform teams. | F16: Not started | G16: Head of Responsible AI
A17: A.5.5 | B17: Assessing societal impacts of AI systems | C17: Yes | D17: Included: in scope for AI products built and provided by the Innovation and Platform teams. | F17: Not started | G17: Head of Responsible AI
A18: A.6.1.2 | B18: Objectives for responsible development of AI system | C18: Yes | D18: Included: in scope for AI products built and provided by the Innovation and Platform teams. | E18: Responsible AI Principles serve as development objectives. | F18: In progress | G18: Head of Responsible AI
A19: A.6.1.3 | B19: Processes for responsible AI system design and development | C19: Yes | D19: Included: in scope for AI products built and provided by the Innovation and Platform teams. | E19: AI SDLC procedure drafted from existing engineering practice. | F19: In progress | G19: Head of Platform
A20: A.6.2.2 | B20: AI system requirements and specification | C20: Yes | D20: Included: in scope for AI products built and provided by the Innovation and Platform teams. | F20: Unverified claim | G20: Head of Platform
A21: A.6.2.3 | B21: Documentation of AI system design and development | C21: Yes | D21: Included: in scope for AI products built and provided by the Innovation and Platform teams. | F21: Unverified claim | G21: Head of Platform
A22: A.6.2.4 | B22: AI system verification and validation | C22: Yes | D22: Included: in scope for AI products built and provided by the Innovation and Platform teams. | E22: CI gate blocks release unless evaluation metrics meet thresholds. | F22: In progress | G22: Head of Platform
A23: A.6.2.5 | B23: AI system deployment | C23: Yes | D23: Included: in scope for AI products built and provided by the Innovation and Platform teams. | E23: Production promotion requires an approved PR and passing gate. | F23: In progress | G23: Head of Platform
A24: A.6.2.6 | B24: AI system operation and monitoring | C24: Yes | D24: Included: in scope for AI products built and provided by the Innovation and Platform teams. | E24: Production telemetry for drift and error rates. | F24: In progress | G24: Head of Platform
A25: A.6.2.7 | B25: AI system technical documentation | C25: Yes | D25: Included: in scope for AI products built and provided by the Innovation and Platform teams. | F25: Not started | G25: Head of Platform
A26: A.6.2.8 | B26: AI system recording of event logs | C26: Yes | D26: Included: in scope for AI products built and provided by the Innovation and Platform teams. | E26: Event logging configured for AI services in Terraform. | F26: In progress | G26: Head of Platform
A27: A.7.2 | B27: Data for development and enhancement of AI system | C27: Yes | D27: Included: in scope for AI products built and provided by the Innovation and Platform teams. | F27: In progress | G27: Security & Compliance
A28: A.7.3 | B28: Acquisition of data | C28: Yes | D28: Included: the Platform team acquires third-party and customer data for model development. | F28: Not started | G28: Head of Platform
A29: A.7.4 | B29: Quality of data for AI systems | C29: Yes | D29: Included: in scope for AI products built and provided by the Innovation and Platform teams. | F29: Unverified claim | G29: Head of Platform
A30: A.7.5 | B30: Data provenance | C30: Yes | D30: Included: in scope for AI products built and provided by the Innovation and Platform teams. | E30: Datasets and checkpoints hashed at ingest; manifests stored with artifacts. | F30: In progress | G30: Head of Platform
A31: A.7.6 | B31: Data preparation | C31: Yes | D31: Included: in scope for AI products built and provided by the Innovation and Platform teams. | F31: Not started | G31: Head of Platform
A32: A.8.2 | B32: System documentation and information for users | C32: Yes | D32: Included: in scope for AI products built and provided by the Innovation and Platform teams. | F32: Not started | G32: Head of Platform
A33: A.8.3 | B33: External reporting | C33: Yes | D33: Included: in scope for AI products built and provided by the Innovation and Platform teams. | F33: Not started | G33: Legal
A34: A.8.4 | B34: Communication of incidents | C34: Yes | D34: Included: in scope for AI products built and provided by the Innovation and Platform teams. | E34: SOC 2 incident process includes customer notification. | F34: In progress | G34: Security & Compliance
A35: A.8.5 | B35: Information for interested parties | C35: Yes | D35: Included: in scope for AI products built and provided by the Innovation and Platform teams. | F35: Not started | G35: Legal
A36: A.9.2 | B36: Processes for responsible use of AI systems | C36: Yes | D36: Included: in scope for AI products built and provided by the Innovation and Platform teams. | E36: Company AI Use Policy covers end-user use; producer-side use not addressed. | F36: In progress | G36: Security & Compliance
A37: A.9.3 | B37: Objectives for responsible use of AI system | C37: Yes | D37: Included: in scope for AI products built and provided by the Innovation and Platform teams. | F37: Not started | G37: Head of Responsible AI
A38: A.9.4 | B38: Intended use of the AI system | C38: Yes | D38: Included: in scope for AI products built and provided by the Innovation and Platform teams. | E38: Agent authority limits enforced in configuration. | F38: Unverified claim | G38: Head of Platform
A39: A.10.2 | B39: Allocating responsibilities | C39: Yes | D39: Included: in scope for AI products built and provided by the Innovation and Platform teams. | F39: Not started | G39: Legal
A40: A.10.3 | B40: Suppliers | C40: Yes | D40: Included: in scope for AI products built and provided by the Innovation and Platform teams. | E40: SOC 2 vendor program exists; AI suppliers not yet reviewed through it. | F40: In progress | G40: Security & Compliance
A41: A.10.4 | B41: Customers | C41: Yes | D41: Included: AI products are delivered to government customers with contractual AI requirements. | F41: Not started | G41: Legal

Sheet Gaps
A1: (Example Client) · ISO 42001 · generated from the GRC record as of 2026-10-24. Read-only export: change the record through pull requests, not here.
A3: ID | B3: Area | C3: Finding | D3: Requirements | E3: Owner | F3: Due | G3: Phase | H3: Severity | I3: Status | J3: Days overdue
A4: GAP-01 | B4: AIMS governance | C4: No producer-scope AIMS AI policy yet; scope draft still needs leadership approval. | D4: 5.2, 4.3, A.2.2 | E4: VP Engineering | F4: 46346 | G4: governance | H4: high | I4: open | J4: =IF(AND(OR(I4="open",I4="in_progress"),ISNUMBER(F4),F4<Summary!$B$4),Summary!$B$4-F4,"")
A5: GAP-02 | B5: Impact assessment | C5: No AI impact assessments have been completed; methodology/template must be established and used. | D5: 6.1.4, 8.4, A.5.2, A.5.3, A.5.4, A.5.5 | E5: Head of Responsible AI | F5: 46374 | G5: implement | H5: high | I5: open | J5: =IF(AND(OR(I5="open",I5="in_progress"),ISNUMBER(F5),F5<Summary!$B$4),Summary!$B$4-F5,"")
A6: GAP-03 | B6: Training & competence | C6: AI-specific training is planned but not yet operating. | D6: 7.2, 7.3, A.4.6 | E6: People Operations | F6: 46374 | G6: implement | H6: medium | I6: open | J6: =IF(AND(OR(I6="open",I6="in_progress"),ISNUMBER(F6),F6<Summary!$B$4),Summary!$B$4-F6,"")
A7: GAP-04 | B7: Data governance | C7: Existing classification taxonomy does not yet cover AI artifacts such as corpora, datasets, checkpoints, and delivered models. | D7: A.4.3, A.7.2, A.7.4 | E7: Security & Compliance | F7: 46351 | G7: governance | H7: medium | I7: open | J7: =IF(AND(OR(I7="open",I7="in_progress"),ISNUMBER(F7),F7<Summary!$B$4),Summary!$B$4-F7,"")
A8: GAP-05 | B8: AI suppliers | C8: AI-specific suppliers have not yet been run through the existing vendor program; supplier contract/DPA requirements are incomplete. | D8: A.10.2, A.10.3, 8.1 | E8: Security & Compliance | F8: 46374 | G8: implement | H8: high | I8: open | J8: =IF(AND(OR(I8="open",I8="in_progress"),ISNUMBER(F8),F8<Summary!$B$4),Summary!$B$4-F8,"")
A9: GAP-06 | B9: Control codification | C9: Some human-review and engineering practices operate in code/process but are not fully reflected in policy text. | D9: A.6.1.3, A.6.2.4, A.6.2.5, A.7.5, A.9.4 | E9: Head of Platform | F9: 46356 | G9: governance | H9: medium | I9: in_progress | J9: =IF(AND(OR(I9="open",I9="in_progress"),ISNUMBER(F9),F9<Summary!$B$4),Summary!$B$4-F9,"")
A10: GAP-07 | B10: Regulatory mapping | C10: Formal per-market AI regulatory/contractual mapping has not yet been performed. | D10: 4.1, 4.2, A.8.5 | E10: Legal | F10: 46356 | G10: governance | H10: medium | I10: open | J10: =IF(AND(OR(I10="open",I10="in_progress"),ISNUMBER(F10),F10<Summary!$B$4),Summary!$B$4-F10,"")
A11: GAP-08 | B11: Internal audit | C11: No standalone AI/AIMS internal audit program or completed AI-scoped internal audit exists. | D11: 9.2 | E11: Security & Compliance | F11: 46409 | G11: test | H11: high | I11: open | J11: =IF(AND(OR(I11="open",I11="in_progress"),ISNUMBER(F11),F11<Summary!$B$4),Summary!$B$4-F11,"")
A12: GAP-09 | B12: Management review | C12: AI is discussed in quarterly leadership review, but a dedicated standing AI/AIMS review structure needs to be formalized. | D12: 9.3, 5.1 | E12: VP Engineering | F12: 46416 | G12: test | H12: medium | I12: open | J12: =IF(AND(OR(I12="open",I12="in_progress"),ISNUMBER(F12),F12<Summary!$B$4),Summary!$B$4-F12,"")
A13: GAP-10 | B13: Statement of Applicability | C13: No SoA exists; Annex A applicability and justifications must be decided and approved. | D13: 6.1.3 | E13: Security & Compliance | F13: 46346 | G13: governance | H13: high | I13: open | J13: =IF(AND(OR(I13="open",I13="in_progress"),ISNUMBER(F13),F13<Summary!$B$4),Summary!$B$4-F13,"")
A14: GAP-11 | B14: Roles | C14: AIMS roles and responsibilities are not documented in a RACI. | D14: 5.3, A.3.2 | E14: VP Engineering | F14: 46339 | G14: governance | H14: medium | I14: open | J14: =IF(AND(OR(I14="open",I14="in_progress"),ISNUMBER(F14),F14<Summary!$B$4),Summary!$B$4-F14,"")
A15: GAP-12 | B15: Concern reporting | C15: No internal or external channel for reporting AI concerns or adverse impacts. | D15: A.3.3, A.8.3 | E15: Legal | F15: 46367 | G15: implement | H15: medium | I15: open | J15: =IF(AND(OR(I15="open",I15="in_progress"),ISNUMBER(F15),F15<Summary!$B$4),Summary!$B$4-F15,"")
A16: GAP-13 | B16: Inventory | C16: Model registry entries lacked an accountable owner field. | D16: A.4.2 | E16: Head of Platform | F16: 46304 | G16: validate | H16: low | I16: closed | J16: =IF(AND(OR(I16="open",I16="in_progress"),ISNUMBER(F16),F16<Summary!$B$4),Summary!$B$4-F16,"")

Sheet Evidence
A1: (Example Client) · ISO 42001 · generated from the GRC record as of 2026-10-24. Read-only export: change the record through pull requests, not here.
A3: ID | B3: Title | C3: Type | D3: Location | E3: Collected | F3: Expires | G3: Status | H3: Approved by | I3: Supports
A4: EV-001 | B4: Draft AIMS scope statement (unapproved) | C4: document | D4: sharepoint://aims/AIMS-Scope-DRAFT-v0.3.docx | E4: 46300 | F4: 46665 | G4: current | I4: 4.1·D, 4.3·D, A.4.2·D
A5: EV-002 | B5: AI systems inventory (4 systems) | C5: record | D5: sharepoint://aims/AI-Inventory.xlsx#Systems | E5: 46300 | F5: 46390 | G5: current | I5: A.4.2·I
A6: EV-003 | B6: Model registry export with owner field populated | C6: record | D6: model-registry://exports/2026-10-07.json | E6: 46302 | F6: 46392 | G6: current | I6: A.4.2·I, A.4.2·E
A7: EV-004 | B7: Drata AI-category risk register export (20 risks) | C7: record | D7: drata://risks?category=AI (export 2026-09-30) | E7: 46295 | F7: 46415 | G7: current | I7: 6.1.2·I, 6.1.2·E, 6.1.3·I, 8.2·I, 8.2·E, 8.3·I
A8: EV-005 | B8: Enterprise risk management methodology (SOC 2) | C8: document | D8: sharepoint://policies/ERM-Methodology-v3.pdf | E8: 46297 | F8: 46662 | G8: current | H8: CISO | I8: 6.1.1·D, 6.1.2·D, 8.2·D
A9: EV-006 | B9: Responsible AI Principles (published 2025) | C9: document | D9: sharepoint://policies/Responsible-AI-Principles.pdf | E9: 45809 | F9: 46174 | G9: EXPIRED | H9: CEO | I9: A.6.1.2·D
A10: EV-007 | B10: Company AI Use Policy (end-user use) | C10: document | D10: sharepoint://policies/AI-Use-Policy-v1.2.pdf | E10: 46297 | F10: 46662 | G10: current | H10: CISO | I10: A.9.2·D
A11: EV-008 | B11: AI lifecycle controls procedure (draft) | C11: document | D11: sharepoint://aims/AI-Lifecycle-Controls-Procedure-DRAFT.docx | E11: 46300 | F11: 46665 | G11: current | I11: 8.1·D, A.6.1.3·D
A12: EV-009 | B12: CI model release and evidence gate (workflow config) | C12: config | D12: git://client-platform/ml-release/.ci/release-gate.yml@main | E12: 46300 | F12: 46390 | G12: current | I12: 8.1·I, A.6.1.3·I, A.6.2.4·I, A.6.2.5·I
A13: EV-010 | B13: Gated evaluation results - last 3 production releases | C13: record | D13: ci://ml-release/release-gate/runs?branch=main&last=3 | E13: 46293 | F13: 46383 | G13: current | I13: A.6.2.4·I, A.6.2.4·E
A14: EV-011 | B14: PR approval records for Q3 model promotions | C14: record | D14: github://pulls?label=model-promotion&merged=2026-07-01..2026-09-30 | E14: 46296 | F14: 46416 | G14: current | I14: A.6.2.4·E, A.6.2.5·I, A.6.2.5·E
A15: EV-012 | B15: Production telemetry dashboard (model drift and error rates) | C15: screenshot | D15: grafana://dashboards/ai-prod-overview (captured 2026-10-03) | E15: 46298 | F15: 46358 | G15: current | I15: 9.1·I, A.6.2.6·I, A.6.2.6·E
A16: EV-013 | B16: Incident management and corrective action procedure (SOC 2) | C16: document | D16: sharepoint://policies/Incident-Management-v4.pdf | E16: 46297 | F16: 46662 | G16: current | H16: CISO | I16: 10.2·D, A.8.4·D
A17: EV-014 | B17: Incident tickets sample, Q3 2026 (includes 1 AI-related) | C17: record | D17: jira://INC?created=2026-07-01..2026-09-30 | E17: 46297 | F17: 46417 | G17: current | I17: 10.2·I, A.8.4·I
A18: EV-015 | B18: Vendor management procedure (SOC 2) | C18: document | D18: sharepoint://policies/Vendor-Management-v2.pdf | E18: 46297 | F18: 46662 | G18: current | H18: CISO | I18: A.10.3·D
A19: EV-016 | B19: Quarterly leadership review minutes, Q3 2026 (AI agenda item) | C19: record | D19: sharepoint://leadership/QBR-2026-Q3-minutes.docx | E19: 46296 | F19: 46416 | G19: current | I19: 5.1·I, 9.3·I
A20: EV-017 | B20: Data classification policy (SOC 2) - no AI artifact classes | C20: document | D20: sharepoint://policies/Data-Classification-v3.pdf | E20: 46297 | F20: 46662 | G20: current | H20: CISO | I20: A.7.2·D
A21: EV-018 | B21: Training-data provenance hash manifests (sample of 3 datasets) | C21: record | D21: s3://ml-artifacts/provenance/manifests/ (sample 2026-10-04) | E21: 46299 | F21: 46389 | G21: current | I21: A.7.5·I, A.7.5·E
A22: EV-019 | B22: Production event-logging configuration for AI services | C22: config | D22: infra://terraform/modules/ai-services/logging.tf@a1b2c3d | E22: 46299 | F22: 46389 | G22: current | I22: A.6.2.8·I, A.6.2.8·E
A23: EV-020 | B23: Document control procedure (SOC 2) | C23: document | D23: sharepoint://policies/Document-Control-v2.pdf | E23: 46297 | F23: 46662 | G23: current | H23: CISO | I23: 7.5·D
A24: EV-021 | B24: Security awareness training completions (FY26) | C24: record | D24: lms://reports/security-awareness-2026 | E24: 46297 | F24: 46417 | G24: current | I24: 7.3·I
A25: EV-022 | B25: Analyst walkthrough: release gate on 2 sampled promotions | C25: test | D25: workpapers/WP-01-release-gate-walkthrough.md | E25: 46302 | F25: 46482 | G25: current | I25: A.6.2.4·T
A26: EV-101 | B26: Engagement repo: main branch protection | C26: config | D26: engagement/evidence/collected/EV-101.json | E26: 46303 | F26: 46333 | G26: current | I26: (unused)
A27: EV-102 | B27: Engagement repo: independent review of merged changes (90 days) | C27: record | D27: engagement/evidence/collected/EV-102.json | E27: 46303 | F27: 46333 | G27: FAILING | I27: (unused)
A28: EV-103 | B28: Engagement repo: validation gate runs | C28: record | D28: engagement/evidence/collected/EV-103.json | E28: 46303 | F28: 46333 | G28: current | I28: (unused)

Sheet Findings
A1: (Example Client) · ISO 42001 · generated from the GRC record as of 2026-10-24. Read-only export: change the record through pull requests, not here.
A3: ID | B3: Grade | C3: Source | D3: Requirement | E3: Status | F3: Owner | G3: Due | H3: Description | I3: Root cause | J3: Corrective action

Sheet Impact assessments
A1: (Example Client) · ISO 42001 · generated from the GRC record as of 2026-10-24. Read-only export: change the record through pull requests, not here.
A3: System | B3: Name | C3: Risk tier | D3: Assessment | E3: Status | F3: Decision | G3: Highest residual | H3: Band | I3: Next review | J3: Current and approved

Sheet Documents
A1: (Example Client) · ISO 42001 · generated from the GRC record as of 2026-10-24. Read-only export: change the record through pull requests, not here.
A3: ID | B3: Title | C3: Type | D3: Status | E3: Version | F3: Owner | G3: Approver | H3: Approved | I3: Next review | J3: Current and approved | K3: Requirements
A4: DOC-SCOPE | B4: AIMS Scope and Context | C4: policy | D4: missing | J4: No | K4: 4.1, 4.2, 4.3, 4.4
A5: DOC-AI-POLICY | B5: AI Policy | C5: policy | D5: missing | J5: No | K5: 5.1, 5.2, A.2.2, A.2.3, A.2.4
A6: DOC-ROLES | B6: AI Roles, Responsibilities and Reporting of Concerns | C6: procedure | D6: missing | J6: No | K6: 5.3, A.3.2, A.3.3, A.10.2
A7: DOC-RISK | B7: AI Risk Management Procedure | C7: procedure | D7: missing | J7: No | K7: 6.1.1, 6.1.2, 6.1.3, 8.2, 8.3
A8: DOC-IMPACT | B8: AI System Impact Assessment Procedure | C8: procedure | D8: missing | J8: No | K8: 6.1.4, 8.4, A.5.2, A.5.3, A.5.4, A.5.5
A9: DOC-OBJECTIVES | B9: AI Objectives and Planning of Changes | C9: procedure | D9: missing | J9: No | K9: 6.2, 6.3, A.6.1.2, A.9.3
A10: DOC-PEOPLE | B10: Resources, Competence, Awareness and Communication | C10: procedure | D10: missing | J10: No | K10: 7.1, 7.2, 7.3, 7.4, A.4.6
A11: DOC-DOCINFO | B11: Control of Documented Information | C11: procedure | D11: missing | J11: No | K11: 7.5
A12: DOC-RESOURCES | B12: AI Resources Inventory Procedure | C12: procedure | D12: missing | J12: No | K12: A.4.2, A.4.3, A.4.4, A.4.5
A13: DOC-LIFECYCLE | B13: AI System Lifecycle Procedure | C13: procedure | D13: missing | J13: No | K13: 8.1, A.6.1.3, A.6.2.2, A.6.2.3, A.6.2.4, A.6.2.5, A.6.2.6, A.6.2.7, A.6.2.8
A14: DOC-DATA | B14: Data for AI Systems Procedure | C14: procedure | D14: missing | J14: No | K14: A.7.2, A.7.3, A.7.4, A.7.5, A.7.6
A15: DOC-COMMS | B15: Information for Users and Interested Parties | C15: procedure | D15: missing | J15: No | K15: A.8.2, A.8.3, A.8.4, A.8.5
... A20: DOC-IMPROVE | B20: Nonconformity, Corrective Action and Improvement | C20: procedure | D20: missing | J20: No | K20: 10.1, 10.2

Sheet Review actions
A1: (Example Client) · ISO 42001 · generated from the GRC record as of 2026-10-24. Read-only export: change the record through pull requests, not here.
A3: Review | B3: Action ID | C3: Action | D3: Owner | E3: Due | F3: Status | G3: Closed | H3: Evidence
